[2024-01-27T22:07:02.130+0000] {taskinstance.py:1103} INFO - Dependencies all met for dep_context=non-requeueable deps ti=<TaskInstance: ETL_1.transform_data manual__2024-01-27T22:06:54.591792+00:00 [queued]>
[2024-01-27T22:07:02.135+0000] {taskinstance.py:1103} INFO - Dependencies all met for dep_context=requeueable deps ti=<TaskInstance: ETL_1.transform_data manual__2024-01-27T22:06:54.591792+00:00 [queued]>
[2024-01-27T22:07:02.135+0000] {taskinstance.py:1308} INFO - Starting attempt 1 of 1
[2024-01-27T22:07:02.173+0000] {taskinstance.py:1327} INFO - Executing <Task(PythonOperator): transform_data> on 2024-01-27 22:06:54.591792+00:00
[2024-01-27T22:07:02.177+0000] {standard_task_runner.py:57} INFO - Started process 38788 to run task
[2024-01-27T22:07:02.180+0000] {standard_task_runner.py:84} INFO - Running: ['airflow', 'tasks', 'run', 'ETL_1', 'transform_data', 'manual__2024-01-27T22:06:54.591792+00:00', '--job-id', '31', '--raw', '--subdir', 'DAGS_FOLDER/ETL_1.py', '--cfg-path', '/tmp/tmpso617in4']
[2024-01-27T22:07:02.180+0000] {standard_task_runner.py:85} INFO - Job 31: Subtask transform_data
[2024-01-27T22:07:02.230+0000] {task_command.py:410} INFO - Running <TaskInstance: ETL_1.transform_data manual__2024-01-27T22:06:54.591792+00:00 [running]> on host codespaces-ca3784
[2024-01-27T22:07:02.321+0000] {taskinstance.py:1545} INFO - Exporting env vars: AIRFLOW_CTX_DAG_OWNER='airflow' AIRFLOW_CTX_DAG_ID='ETL_1' AIRFLOW_CTX_TASK_ID='transform_data' AIRFLOW_CTX_EXECUTION_DATE='2024-01-27T22:06:54.591792+00:00' AIRFLOW_CTX_TRY_NUMBER='1' AIRFLOW_CTX_DAG_RUN_ID='manual__2024-01-27T22:06:54.591792+00:00'
[2024-01-27T22:07:02.341+0000] {taskinstance.py:1824} ERROR - Task failed with exception
Traceback (most recent call last):
  File "/usr/local/python/3.10.13/lib/python3.10/site-packages/airflow/operators/python.py", line 181, in execute
    return_value = self.execute_callable()
  File "/usr/local/python/3.10.13/lib/python3.10/site-packages/airflow/operators/python.py", line 198, in execute_callable
    return self.python_callable(*self.op_args, **self.op_kwargs)
  File "/workspaces/hands-on-introduction-data-engineering-4395021/airflow/dags/ETL_1.py", line 42, in transform_data
    for column, dtype in trans_data.dtypes.iteritems():
  File "/home/codespace/.local/lib/python3.10/site-packages/pandas/core/generic.py", line 6204, in __getattr__
    return object.__getattribute__(self, name)
AttributeError: 'Series' object has no attribute 'iteritems'
[2024-01-27T22:07:02.353+0000] {taskinstance.py:1345} INFO - Marking task as FAILED. dag_id=ETL_1, task_id=transform_data, execution_date=20240127T220654, start_date=20240127T220702, end_date=20240127T220702
[2024-01-27T22:07:02.386+0000] {standard_task_runner.py:104} ERROR - Failed to execute job 31 for task transform_data ('Series' object has no attribute 'iteritems'; 38788)
[2024-01-27T22:07:02.432+0000] {local_task_job_runner.py:225} INFO - Task exited with return code 1
[2024-01-27T22:07:02.445+0000] {taskinstance.py:2653} INFO - 0 downstream tasks scheduled from follow-on schedule check
