[2024-01-27T20:35:34.892+0000] {taskinstance.py:1103} INFO - Dependencies all met for dep_context=non-requeueable deps ti=<TaskInstance: ETL_1.transform_data manual__2024-01-27T20:35:27.499274+00:00 [queued]>
[2024-01-27T20:35:34.897+0000] {taskinstance.py:1103} INFO - Dependencies all met for dep_context=requeueable deps ti=<TaskInstance: ETL_1.transform_data manual__2024-01-27T20:35:27.499274+00:00 [queued]>
[2024-01-27T20:35:34.897+0000] {taskinstance.py:1308} INFO - Starting attempt 1 of 1
[2024-01-27T20:35:34.931+0000] {taskinstance.py:1327} INFO - Executing <Task(PythonOperator): transform_data> on 2024-01-27 20:35:27.499274+00:00
[2024-01-27T20:35:34.935+0000] {standard_task_runner.py:57} INFO - Started process 4347 to run task
[2024-01-27T20:35:34.937+0000] {standard_task_runner.py:84} INFO - Running: ['airflow', 'tasks', 'run', 'ETL_1', 'transform_data', 'manual__2024-01-27T20:35:27.499274+00:00', '--job-id', '17', '--raw', '--subdir', 'DAGS_FOLDER/ETL_1.py', '--cfg-path', '/tmp/tmpg62n05hm']
[2024-01-27T20:35:34.938+0000] {standard_task_runner.py:85} INFO - Job 17: Subtask transform_data
[2024-01-27T20:35:34.986+0000] {task_command.py:410} INFO - Running <TaskInstance: ETL_1.transform_data manual__2024-01-27T20:35:27.499274+00:00 [running]> on host codespaces-ca3784
[2024-01-27T20:35:35.070+0000] {taskinstance.py:1545} INFO - Exporting env vars: AIRFLOW_CTX_DAG_OWNER='airflow' AIRFLOW_CTX_DAG_ID='ETL_1' AIRFLOW_CTX_TASK_ID='transform_data' AIRFLOW_CTX_EXECUTION_DATE='2024-01-27T20:35:27.499274+00:00' AIRFLOW_CTX_TRY_NUMBER='1' AIRFLOW_CTX_DAG_RUN_ID='manual__2024-01-27T20:35:27.499274+00:00'
[2024-01-27T20:35:35.134+0000] {taskinstance.py:1824} ERROR - Task failed with exception
Traceback (most recent call last):
  File "/usr/local/python/3.10.13/lib/python3.10/site-packages/airflow/operators/python.py", line 181, in execute
    return_value = self.execute_callable()
  File "/usr/local/python/3.10.13/lib/python3.10/site-packages/airflow/operators/python.py", line 198, in execute_callable
    return self.python_callable(*self.op_args, **self.op_kwargs)
  File "/workspaces/hands-on-introduction-data-engineering-4395021/airflow/dags/ETL_1.py", line 40, in transform_data
    trans_data.csv('/workspaces/hands-on-introduction-data-engineering-4395021/lab/monthly_info.csv')
  File "/home/codespace/.local/lib/python3.10/site-packages/pandas/core/generic.py", line 6204, in __getattr__
    return object.__getattribute__(self, name)
AttributeError: 'DataFrame' object has no attribute 'csv'. Did you mean: 'cov'?
[2024-01-27T20:35:35.141+0000] {taskinstance.py:1345} INFO - Marking task as FAILED. dag_id=ETL_1, task_id=transform_data, execution_date=20240127T203527, start_date=20240127T203534, end_date=20240127T203535
[2024-01-27T20:35:35.172+0000] {standard_task_runner.py:104} ERROR - Failed to execute job 17 for task transform_data ('DataFrame' object has no attribute 'csv'; 4347)
[2024-01-27T20:35:35.190+0000] {local_task_job_runner.py:225} INFO - Task exited with return code 1
[2024-01-27T20:35:35.206+0000] {taskinstance.py:2653} INFO - 0 downstream tasks scheduled from follow-on schedule check
